Workbook
Name DiscountRate: Einstellungen!$B$3
Name HorizonYears: Einstellungen!$B$4
Name TaxRate: Einstellungen!$B$5
Name VariableNames: Variablen!$A$4:INDEX(Variablen!$A:$A,COUNTA(Variablen!$A:$A))
Name ActionIDs: Actions!$A$2:INDEX(Actions!$A:$A,COUNTA(Actions!$A:$A))
Name KPIList: Helper!$A$2#

Sheet Glossar
A1: Glossar: Begriffe und Abkürzungen
A3: Ziel: Kurze Erklärungen, damit auch Nicht-Finanzleute die Logik nachvollziehen können.
A5: Begriffe
A6: Begriff | B6: Erklärung
A7: CAPEX | B7: Einmalige Investitionsausgaben (z.B. Hardware, Installation). In dieser Datei wird CAPEX in Jahr 0 als Auszahlung angesetzt.
A8: OPEX | B8: Laufende Kosten pro Jahr (z.B. Wartung, Lizenzen). In dieser Datei starten OPEX ab Go-Live und werden im Go-Live-Jahr anteilig gerechnet.
A9: ROI | B9: Return on Investment. Hier vereinfacht: Verhältnis von Netto-Nutzen zu (CAPEX + OPEX) über den Betrachtungszeitraum. Gut für einen schnellen Vergleich, aber weniger sauber als NPV.
A10: NPV / Kapitalwert | B10: Summe aller zukünftigen Cashflows, abgezinst auf heute. Positiv bedeutet: wirtschaftlich attraktiv bei gegebenem Diskontsatz.
A11: Diskontsatz | B11: Zinssatz, mit dem zukünftige Cashflows auf heute abgezinst werden (z.B. WACC). Höherer Diskontsatz macht zukünftige Nutzen weniger wert.
A12: IRR | B12: Interner Zinsfuß. Der Diskontsatz, bei dem der Kapitalwert genau 0 ist. Hilft beim Vergleich von Projekten, kann aber bei untypischen Cashflows irreführend sein.
A13: Payback / Amortisation | B13: Zeitpunkt, an dem die kumulierten Cashflows erstmals wieder positiv sind (Investition hat sich zurückgezahlt). Ignoriert Cashflows nach dem Payback und Diskontierung.
A14: Go-Live | B14: Zeitpunkt, ab dem die Maßnahme wirkt und Nutzen sowie OPEX starten. In dieser Datei: Zieldatum.
A15: Monetarisierung | B15: Übersetzung eines KPI-Impacts in Euro pro Einheit (z.B. EUR/kWh). Kann fix sein oder über eine Variable (z.B. Strompreis je Jahr).
A16: Variable | B16: Zeitreihe mit Kalenderjahren (z.B. Strompreis 2020 bis 2055). Jede Variable hat ein eigenes Startjahr und einen eigenen Horizont.
A17: MACC (pro KPI) | B17: Marginal Abatement Cost Curve. Hier: Kosten pro Einheit KPI-Reduktion (€/Einheit). Berechnet als -NPV / diskontierte KPI-Reduktion. MACC ist nur sinnvoll innerhalb eines KPI, weil Einheiten unterschiedlich sind.

Sheet README
A1: ROI & Investitionsplanung für Nachhaltigkeits-Actions (Vorlage v5)
A3: Zweck: Pro Action und als Portfolio eine transparente Investitionsrechnung (NPV, IRR, ROI, Payback).
A4: Neu: MACC wird pro Nachhaltigkeits-KPI dargestellt (nicht nur CO2).
A6: Schritt-für-Schritt:
A7: 1) Trage Actions im Blatt „Actions“ ein. Blau sind Eingaben. Schwarzer Text sind Formeln oder automatisch gezogene Werte.
A8: 2) Trage bei Bedarf Variablen im Blatt „Variablen“ ein (z.B. Strompreis). Jede Variable hat eigenes Startjahr und eigenen Horizont.
A9: 3) Setze globale Annahmen in „Einstellungen“ (Diskontsatz, TaxRate, Horizont).
A10: 4) Nutze „Action_Rechner“ als Detailansicht je Action.
A11: 5) Nutze „Dashboard“ für die Portfolio-Übersicht und „MACC_KPI“ für MACC pro KPI.
A13: Wichtige Modellannahmen:
A14: • Nutzen und OPEX starten ab Go-Live (Zieldatum). Im Go-Live-Jahr anteilig nach Monaten: (12 - Monat(Go-Live) + 1) / 12.
A15: • CAPEX wird als Auszahlung in Jahr 0 (relativ zum Startjahr) angesetzt.
... A19: Komplexität bewusst niedrig: Das Modell priorisiert Actions. Für Investitionsfreigaben brauchst du in der Praxis oft mehr Details (Timing von CAPEX, Ramp-up, Risiken, Sensitivitäten).

Sheet Einstellungen
A1: Globale Annahmen
A3: Diskontsatz (WACC/Discount Rate) | B3: 0.08 | C3: Dezimal, z.B. 0,08 für 8%
A4: Cashflow-Horizont (Jahre) | B4: 10 | C4: max 20 (in Cashflow-Tabellen)
A5: TaxRate (Steuersatz) | B5: 0.3 | C5: 0 setzen, wenn du Steuern/Abschreibung ignorieren willst
A6: Währung | B6: EUR

Sheet CAPEX_OPEX_Glossar
A1: CAPEX und OPEX (Orientierung)
A3: Kategorie | B3: Typische Inhalte
A4: CAPEX Equipment | B4: Maschinen, Hardware, Anlagen, Sensorik, Ersatzinvestitionen, Gebäudeanpassungen
A5: CAPEX Installation | B5: Montage, Inbetriebnahme, Umbauten, Projektmanagement (einmalig)
A6: CAPEX Software | B6: Einmalige Software-Käufe, Implementierung, Setup, Integrationsaufwand
A7: CAPEX Beratung | B7: Externe Beratung, Engineering, Audits (einmalig)
A8: CAPEX Sonstiges | B8: Schulung (einmalig), Genehmigungen, Messkonzept-Aufbau, sonstige Einmalaufwände
A9: OPEX Wartung | B9: Wartung, Ersatzteile, Service, Kalibrierung
A10: OPEX Lizenzen | B10: SaaS-Abos, laufende Software-Lizenzen
A11: OPEX Personal | B11: Betrieb, Monitoring, Reporting, zusätzliche interne Kapazität
A12: OPEX Sonstiges | B12: Versicherung, Miete, Gebühren, sonstige Betriebskosten

Sheet Variablen
A1: Variablen (kalenderjahresbasiert, pro Variable eigenes Startjahr & Horizont)
A2: Vor Startjahr: leer. Nach Ende (Startjahr + Horizont): konstant. Methode Manuell: Werte direkt in Jahres-Spalten überschreiben.
A3: Variable Name | B3: Beschreibung | C3: Einheit | D3: Methode (Fix/CAGR/Manuell) | E3: Startjahr | F3: Horizont (Jahre) | G3: Wert im Startjahr | H3: Wachstum p.a. (CAGR) | I3: 2018 | J3: 2019 | K3: 2020 | L3: 2021 | M3: 2022 | N3: 2023 | O3: 2024 | P3: 2025 | Q3: 2026 | R3: 2027 | S3: 2028 | T3: 2029 | U3: 2030 | V3: 2031 | W3: 2032 | X3: 2033 | Y3: 2034 | Z3: 2035 | AA3: 2036 | AB3: 2037 | AC3: 2038 | AD3: 2039 | AE3: 2040 | AF3: 2041 | AG3: 2042 | AH3: 2043 | AI3: 2044 | AJ3: 2045 | AK3: 2046 | AL3: 2047 | AM3: 2048 | AN3: 2049 | AO3: 2050 | AP3: 2051 | AQ3: 2052 | AR3: 2053 | AS3: 2054 | AT3: 2055
A4: Strompreis | B4: Strompreis | C4: EUR/kWh | D4: CAGR | E4: 2020 | F4: 25 | G4: 0.22 | H4: 0.03 | I4: =IF($A4="","",IF(2018<$E4,"",IF($D4="Manuell","",IF(2018>$E4+$F4,IF($D4="Fix",$G4,$G4*(1+$H4)^($F4)),IF($D4="Fix",$G4,$G4*(1+$H4)^(2018-$E4)))))) | J4: =IF($A4="","",IF(2019<$E4,"",IF($D4="Manuell","",IF(2019>$E4+$F4,IF($D4="Fix",$G4,$G4*(1+$H4)^($F4)),IF($D4="Fix",$G4,$G4*(1+$H4)^(2019-$E4)))))) | K4: =IF($A4="","",IF(2020<$E4,"",IF($D4="Manuell","",IF(2020>$E4+$F4,IF($D4="Fix",$G4,$G4*(1+$H4)^($F4)),IF($D4="Fix",$G4,$G4*(1+$H4)^(2020-$E4)))))) | L4: =IF($A4="","",IF(2021<$E4,"",IF($D4="Manuell","",IF(2021>$E4+$F4,IF($D4="Fix",$G4,$G4*(1+$H4)^($F4)),IF($D4="Fix",$G4,$G4*(1+$H4)^(2021-$E4)))))) | M4: =IF($A4="","",IF(2022<$E4,"",IF($D4="Manuell","",IF(2022>$E4+$F4,IF($D4="Fix",$G4,$G4*(1+$H4)^($F4)),IF($D4="Fix",$G4,$G4*(1+$H4)^(2022-$E4)))))) | N4: =IF($A4="","",IF(2023<$E4,"",IF($D4="Manuell","",IF(2023>$E4+$F4,IF($D4="Fix",$G4,$G4*(1+$H4)^($F4)),IF($D4="Fix",$G4,$G4*(1+$H4)^(2023-$E4)))))) | O4: =IF($A4="","",IF(2024<$E4,"",IF($D4="Manuell","",IF(2024>$E4+$F4,IF($D4="Fix",$G4,$G4*(1+$H4)^($F4)),IF($D4="Fix",$G4,$G4*(1+$H4)^(2024-$E4)))))) | P4: =IF($A4="","",IF(2025<$E4,"",IF($D4="Manuell","",IF(2025>$E4+$F4,IF($D4="Fix",$G4,$G4*(1+$H4)^($F4)),IF($D4="Fix",$G4,$G4*(1+$H4)^(2025-$E4)))))) | Q4: =IF($A4="","",IF(2026<$E4,"",IF($D4="Manuell","",IF(2026>$E4+$F4,IF($D4="Fix",$G4,$G4*(1+$H4)^($F4)),IF($D4="Fix",$G4,$G4*(1+$H4)^(2026-$E4)))))) | R4: =IF($A4="","",IF(2027<$E4,"",IF($D4="Manuell","",IF(2027>$E4+$F4,IF($D4="Fix",$G4,$G4*(1+$H4)^($F4)),IF($D4="Fix",$G4,$G4*(1+$H4)^(2027-$E4)))))) | S4: =IF($A4="","",IF(2028<$E4,"",IF($D4="Manuell","",IF(2028>$E4+$F4,IF($D4="Fix",$G4,$G4*(1+$H4)^($F4)),IF($D4="Fix",$G4,$G4*(1+$H4)^(2028-$E4)))))) | T4: =IF($A4="","",IF(2029<$E4,"",IF($D4="Manuell","",IF(2029>$E4+$F4,IF($D4="Fix",$G4,$G4*(1+$H4)^($F4)),IF($D4="Fix",$G4,$G4*(1+$H4)^(2029-$E4)))))) | U4: =IF($A4="","",IF(2030<$E4,"",IF($D4="Manuell","",IF(2030>$E4+$F4,IF($D4="Fix",$G4,$G4*(1+$H4)^($F4)),IF($D4="Fix",$G4,$G4*(1+$H4)^(2030-$E4)))))) | V4: =IF($A4="","",IF(2031<$E4,"",IF($D4="Manuell","",IF(2031>$E4+$F4,IF($D4="Fix",$G4,$G4*(1+$H4)^($F4)),IF($D4="Fix",$G4,$G4*(1+$H4)^(2031-$E4)))))) | W4: =IF($A4="","",IF(2032<$E4,"",IF($D4="Manuell","",IF(2032>$E4+$F4,IF($D4="Fix",$G4,$G4*(1+$H4)^($F4)),IF($D4="Fix",$G4,$G4*(1+$H4)^(2032-$E4)))))) | X4: =IF($A4="","",IF(2033<$E4,"",IF($D4="Manuell","",IF(2033>$E4+$F4,IF($D4="Fix",$G4,$G4*(1+$H4)^($F4)),IF($D4="Fix",$G4,$G4*(1+$H4)^(2033-$E4)))))) | Y4: =IF($A4="","",IF(2034<$E4,"",IF($D4="Manuell","",IF(2034>$E4+$F4,IF($D4="Fix",$G4,$G4*(1+$H4)^($F4)),IF($D4="Fix",$G4,$G4*(1+$H4)^(2034-$E4)))))) | Z4: =IF($A4="","",IF(2035<$E4,"",IF($D4="Manuell","",IF(2035>$E4+$F4,IF($D4="Fix",$G4,$G4*(1+$H4)^($F4)),IF($D4="Fix",$G4,$G4*(1+$H4)^(2035-$E4)))))) | AA4: =IF($A4="","",IF(2036<$E4,"",IF($D4="Manuell","",IF(2036>$E4+$F4,IF($D4="Fix",$G4,$G4*(1+$H4)^($F4)),IF($D4="Fix",$G4,$G4*(1+$H4)^(2036-$E4)))))) | AB4: =IF($A4="","",IF(2037<$E4,"",IF($D4="Manuell","",IF(2037>$E4+$F4,IF($D4="Fix",$G4,$G4*(1+$H4)^($F4)),IF($D4="Fix",$G4,$G4*(1+$H4)^(2037-$E4)))))) | AC4: =IF($A4="","",IF(2038<$E4,"",IF($D4="Manuell","",IF(2038>$E4+$F4,IF($D4="Fix",$G4,$G4*(1+$H4)^($F4)),IF($D4="Fix",$G4,$G4*(1+$H4)^(2038-$E4)))))) | AD4: =IF($A4="","",IF(2039<$E4,"",IF($D4="Manuell","",IF(2039>$E4+$F4,IF($D4="Fix",$G4,$G4*(1+$H4)^($F4)),IF($D4="Fix",$G4,$G4*(1+$H4)^(2039-$E4)))))) | AE4: =IF($A4="","",IF(2040<$E4,"",IF($D4="Manuell","",IF(2040>$E4+$F4,IF($D4="Fix",$G4,$G4*(1+$H4)^($F4)),IF($D4="Fix",$G4,$G4*(1+$H4)^(2040-$E4)))))) | AF4: =IF($A4="","",IF(2041<$E4,"",IF($D4="Manuell","",IF(2041>$E4+$F4,IF($D4="Fix",$G4,$G4*(1+$H4)^($F4)),IF($D4="Fix",$G4,$G4*(1+$H4)^(2041-$E4)))))) | AG4: =IF($A4="","",IF(2042<$E4,"",IF($D4="Manuell","",IF(2042>$E4+$F4,IF($D4="Fix",$G4,$G4*(1+$H4)^($F4)),IF($D4="Fix",$G4,$G4*(1+$H4)^(2042-$E4)))))) | AH4: =IF($A4="","",IF(2043<$E4,"",IF($D4="Manuell","",IF(2043>$E4+$F4,IF($D4="Fix",$G4,$G4*(1+$H4)^($F4)),IF($D4="Fix",$G4,$G4*(1+$H4)^(2043-$E4)))))) | AI4: =IF($A4="","",IF(2044<$E4,"",IF($D4="Manuell","",IF(2044>$E4+$F4,IF($D4="Fix",$G4,$G4*(1+$H4)^($F4)),IF($D4="Fix",$G4,$G4*(1+$H4)^(2044-$E4)))))) | AJ4: =IF($A4="","",IF(2045<$E4,"",IF($D4="Manuell","",IF(2045>$E4+$F4,IF($D4="Fix",$G4,$G4*(1+$H4)^($F4)),IF($D4="Fix",$G4,$G4*(1+$H4)^(2045-$E4)))))) | AK4: =IF($A4="","",IF(2046<$E4,"",IF($D4="Manuell","",IF(2046>$E4+$F4,IF($D4="Fix",$G4,$G4*(1+$H4)^($F4)),IF($D4="Fix",$G4,$G4*(1+$H4)^(2046-$E4)))))) | AL4: =IF($A4="","",IF(2047<$E4,"",IF($D4="Manuell","",IF(2047>$E4+$F4,IF($D4="Fix",$G4,$G4*(1+$H4)^($F4)),IF($D4="Fix",$G4,$G4*(1+$H4)^(2047-$E4)))))) | AM4: =IF($A4="","",IF(2048<$E4,"",IF($D4="Manuell","",IF(2048>$E4+$F4,IF($D4="Fix",$G4,$G4*(1+$H4)^($F4)),IF($D4="Fix",$G4,$G4*(1+$H4)^(2048-$E4)))))) | AN4: =IF($A4="","",IF(2049<$E4,"",IF($D4="Manuell","",IF(2049>$E4+$F4,IF($D4="Fix",$G4,$G4*(1+$H4)^($F4)),IF($D4="Fix",$G4,$G4*(1+$H4)^(2049-$E4)))))) | AO4: =IF($A4="","",IF(2050<$E4,"",IF($D4="Manuell","",IF(2050>$E4+$F4,IF($D4="Fix",$G4,$G4*(1+$H4)^($F4)),IF($D4="Fix",$G4,$G4*(1+$H4)^(2050-$E4)))))) | AP4: =IF($A4="","",IF(2051<$E4,"",IF($D4="Manuell","",IF(2051>$E4+$F4,IF($D4="Fix",$G4,$G4*(1+$H4)^($F4)),IF($D4="Fix",$G4,$G4*(1+$H4)^(2051-$E4)))))) | AQ4: =IF($A4="","",IF(2052<$E4,"",IF($D4="Manuell","",IF(2052>$E4+$F4,IF($D4="Fix",$G4,$G4*(1+$H4)^($F4)),IF($D4="Fix",$G4,$G4*(1+$H4)^(2052-$E4)))))) | AR4: =IF($A4="","",IF(2053<$E4,"",IF($D4="Manuell","",IF(2053>$E4+$F4,IF($D4="Fix",$G4,$G4*(1+$H4)^($F4)),IF($D4="Fix",$G4,$G4*(1+$H4)^(2053-$E4)))))) | AS4: =IF($A4="","",IF(2054<$E4,"",IF($D4="Manuell","",IF(2054>$E4+$F4,IF($D4="Fix",$G4,$G4*(1+$H4)^($F4)),IF($D4="Fix",$G4,$G4*(1+$H4)^(2054-$E4)))))) | AT4: =IF($A4="","",IF(2055<$E4,"",IF($D4="Manuell","",IF(2055>$E4+$F4,IF($D4="Fix",$G4,$G4*(1+$H4)^($F4)),IF($D4="Fix",$G4,$G4*(1+$H4)^(2055-$E4))))))
A5: Gaspreis | B5: Gaspreis | C5: EUR/kWh | D5: CAGR | E5: 2020 | F5: 25 | G5: 0.07 | H5: 0.02 | I5: =IF($A5="","",IF(2018<$E5,"",IF($D5="Manuell","",IF(2018>$E5+$F5,IF($D5="Fix",$G5,$G5*(1+$H5)^($F5)),IF($D5="Fix",$G5,$G5*(1+$H5)^(2018-$E5)))))) | J5: =IF($A5="","",IF(2019<$E5,"",IF($D5="Manuell","",IF(2019>$E5+$F5,IF($D5="Fix",$G5,$G5*(1+$H5)^($F5)),IF($D5="Fix",$G5,$G5*(1+$H5)^(2019-$E5)))))) | K5: =IF($A5="","",IF(2020<$E5,"",IF($D5="Manuell","",IF(2020>$E5+$F5,IF($D5="Fix",$G5,$G5*(1+$H5)^($F5)),IF($D5="Fix",$G5,$G5*(1+$H5)^(2020-$E5)))))) | L5: =IF($A5="","",IF(2021<$E5,"",IF($D5="Manuell","",IF(2021>$E5+$F5,IF($D5="Fix",$G5,$G5*(1+$H5)^($F5)),IF($D5="Fix",$G5,$G5*(1+$H5)^(2021-$E5)))))) | M5: =IF($A5="","",IF(2022<$E5,"",IF($D5="Manuell","",IF(2022>$E5+$F5,IF($D5="Fix",$G5,$G5*(1+$H5)^($F5)),IF($D5="Fix",$G5,$G5*(1+$H5)^(2022-$E5)))))) | N5: =IF($A5="","",IF(2023<$E5,"",IF($D5="Manuell","",IF(2023>$E5+$F5,IF($D5="Fix",$G5,$G5*(1+$H5)^($F5)),IF($D5="Fix",$G5,$G5*(1+$H5)^(2023-$E5)))))) | O5: =IF($A5="","",IF(2024<$E5,"",IF($D5="Manuell","",IF(2024>$E5+$F5,IF($D5="Fix",$G5,$G5*(1+$H5)^($F5)),IF($D5="Fix",$G5,$G5*(1+$H5)^(2024-$E5)))))) | P5: =IF($A5="","",IF(2025<$E5,"",IF($D5="Manuell","",IF(2025>$E5+$F5,IF($D5="Fix",$G5,$G5*(1+$H5)^($F5)),IF($D5="Fix",$G5,$G5*(1+$H5)^(2025-$E5)))))) | Q5: =IF($A5="","",IF(2026<$E5,"",IF($D5="Manuell","",IF(2026>$E5+$F5,IF($D5="Fix",$G5,$G5*(1+$H5)^($F5)),IF($D5="Fix",$G5,$G5*(1+$H5)^(2026-$E5)))))) | R5: =IF($A5="","",IF(2027<$E5,"",IF($D5="Manuell","",IF(2027>$E5+$F5,IF($D5="Fix",$G5,$G5*(1+$H5)^($F5)),IF($D5="Fix",$G5,$G5*(1+$H5)^(2027-$E5)))))) | S5: =IF($A5="","",IF(2028<$E5,"",IF($D5="Manuell","",IF(2028>$E5+$F5,IF($D5="Fix",$G5,$G5*(1+$H5)^($F5)),IF($D5="Fix",$G5,$G5*(1+$H5)^(2028-$E5)))))) | T5: =IF($A5="","",IF(2029<$E5,"",IF($D5="Manuell","",IF(2029>$E5+$F5,IF($D5="Fix",$G5,$G5*(1+$H5)^($F5)),IF($D5="Fix",$G5,$G5*(1+$H5)^(2029-$E5)))))) | U5: =IF($A5="","",IF(2030<$E5,"",IF($D5="Manuell","",IF(2030>$E5+$F5,IF($D5="Fix",$G5,$G5*(1+$H5)^($F5)),IF($D5="Fix",$G5,$G5*(1+$H5)^(2030-$E5)))))) | V5: =IF($A5="","",IF(2031<$E5,"",IF($D5="Manuell","",IF(2031>$E5+$F5,IF($D5="Fix",$G5,$G5*(1+$H5)^($F5)),IF($D5="Fix",$G5,$G5*(1+$H5)^(2031-$E5)))))) | W5: =IF($A5="","",IF(2032<$E5,"",IF($D5="Manuell","",IF(2032>$E5+$F5,IF($D5="Fix",$G5,$G5*(1+$H5)^($F5)),IF($D5="Fix",$G5,$G5*(1+$H5)^(2032-$E5)))))) | X5: =IF($A5="","",IF(2033<$E5,"",IF($D5="Manuell","",IF(2033>$E5+$F5,IF($D5="Fix",$G5,$G5*(1+$H5)^($F5)),IF($D5="Fix",$G5,$G5*(1+$H5)^(2033-$E5)))))) | Y5: =IF($A5="","",IF(2034<$E5,"",IF($D5="Manuell","",IF(2034>$E5+$F5,IF($D5="Fix",$G5,$G5*(1+$H5)^($F5)),IF($D5="Fix",$G5,$G5*(1+$H5)^(2034-$E5)))))) | Z5: =IF($A5="","",IF(2035<$E5,"",IF($D5="Manuell","",IF(2035>$E5+$F5,IF($D5="Fix",$G5,$G5*(1+$H5)^($F5)),IF($D5="Fix",$G5,$G5*(1+$H5)^(2035-$E5)))))) | AA5: =IF($A5="","",IF(2036<$E5,"",IF($D5="Manuell","",IF(2036>$E5+$F5,IF($D5="Fix",$G5,$G5*(1+$H5)^($F5)),IF($D5="Fix",$G5,$G5*(1+$H5)^(2036-$E5)))))) | AB5: =IF($A5="","",IF(2037<$E5,"",IF($D5="Manuell","",IF(2037>$E5+$F5,IF($D5="Fix",$G5,$G5*(1+$H5)^($F5)),IF($D5="Fix",$G5,$G5*(1+$H5)^(2037-$E5)))))) | AC5: =IF($A5="","",IF(2038<$E5,"",IF($D5="Manuell","",IF(2038>$E5+$F5,IF($D5="Fix",$G5,$G5*(1+$H5)^($F5)),IF($D5="Fix",$G5,$G5*(1+$H5)^(2038-$E5)))))) | AD5: =IF($A5="","",IF(2039<$E5,"",IF($D5="Manuell","",IF(2039>$E5+$F5,IF($D5="Fix",$G5,$G5*(1+$H5)^($F5)),IF($D5="Fix",$G5,$G5*(1+$H5)^(2039-$E5)))))) | AE5: =IF($A5="","",IF(2040<$E5,"",IF($D5="Manuell","",IF(2040>$E5+$F5,IF($D5="Fix",$G5,$G5*(1+$H5)^($F5)),IF($D5="Fix",$G5,$G5*(1+$H5)^(2040-$E5)))))) | AF5: =IF($A5="","",IF(2041<$E5,"",IF($D5="Manuell","",IF(2041>$E5+$F5,IF($D5="Fix",$G5,$G5*(1+$H5)^($F5)),IF($D5="Fix",$G5,$G5*(1+$H5)^(2041-$E5)))))) | AG5: =IF($A5="","",IF(2042<$E5,"",IF($D5="Manuell","",IF(2042>$E5+$F5,IF($D5="Fix",$G5,$G5*(1+$H5)^($F5)),IF($D5="Fix",$G5,$G5*(1+$H5)^(2042-$E5)))))) | AH5: =IF($A5="","",IF(2043<$E5,"",IF($D5="Manuell","",IF(2043>$E5+$F5,IF($D5="Fix",$G5,$G5*(1+$H5)^($F5)),IF($D5="Fix",$G5,$G5*(1+$H5)^(2043-$E5)))))) | AI5: =IF($A5="","",IF(2044<$E5,"",IF($D5="Manuell","",IF(2044>$E5+$F5,IF($D5="Fix",$G5,$G5*(1+$H5)^($F5)),IF($D5="Fix",$G5,$G5*(1+$H5)^(2044-$E5)))))) | AJ5: =IF($A5="","",IF(2045<$E5,"",IF($D5="Manuell","",IF(2045>$E5+$F5,IF($D5="Fix",$G5,$G5*(1+$H5)^($F5)),IF($D5="Fix",$G5,$G5*(1+$H5)^(2045-$E5)))))) | AK5: =IF($A5="","",IF(2046<$E5,"",IF($D5="Manuell","",IF(2046>$E5+$F5,IF($D5="Fix",$G5,$G5*(1+$H5)^($F5)),IF($D5="Fix",$G5,$G5*(1+$H5)^(2046-$E5)))))) | AL5: =IF($A5="","",IF(2047<$E5,"",IF($D5="Manuell","",IF(2047>$E5+$F5,IF($D5="Fix",$G5,$G5*(1+$H5)^($F5)),IF($D5="Fix",$G5,$G5*(1+$H5)^(2047-$E5)))))) | AM5: =IF($A5="","",IF(2048<$E5,"",IF($D5="Manuell","",IF(2048>$E5+$F5,IF($D5="Fix",$G5,$G5*(1+$H5)^($F5)),IF($D5="Fix",$G5,$G5*(1+$H5)^(2048-$E5)))))) | AN5: =IF($A5="","",IF(2049<$E5,"",IF($D5="Manuell","",IF(2049>$E5+$F5,IF($D5="Fix",$G5,$G5*(1+$H5)^($F5)),IF($D5="Fix",$G5,$G5*(1+$H5)^(2049-$E5)))))) | AO5: =IF($A5="","",IF(2050<$E5,"",IF($D5="Manuell","",IF(2050>$E5+$F5,IF($D5="Fix",$G5,$G5*(1+$H5)^($F5)),IF($D5="Fix",$G5,$G5*(1+$H5)^(2050-$E5)))))) | AP5: =IF($A5="","",IF(2051<$E5,"",IF($D5="Manuell","",IF(2051>$E5+$F5,IF($D5="Fix",$G5,$G5*(1+$H5)^($F5)),IF($D5="Fix",$G5,$G5*(1+$H5)^(2051-$E5)))))) | AQ5: =IF($A5="","",IF(2052<$E5,"",IF($D5="Manuell","",IF(2052>$E5+$F5,IF($D5="Fix",$G5,$G5*(1+$H5)^($F5)),IF($D5="Fix",$G5,$G5*(1+$H5)^(2052-$E5)))))) | AR5: =IF($A5="","",IF(2053<$E5,"",IF($D5="Manuell","",IF(2053>$E5+$F5,IF($D5="Fix",$G5,$G5*(1+$H5)^($F5)),IF($D5="Fix",$G5,$G5*(1+$H5)^(2053-$E5)))))) | AS5: =IF($A5="","",IF(2054<$E5,"",IF($D5="Manuell","",IF(2054>$E5+$F5,IF($D5="Fix",$G5,$G5*(1+$H5)^($F5)),IF($D5="Fix",$G5,$G5*(1+$H5)^(2054-$E5)))))) | AT5: =IF($A5="","",IF(2055<$E5,"",IF($D5="Manuell","",IF(2055>$E5+$F5,IF($D5="Fix",$G5,$G5*(1+$H5)^($F5)),IF($D5="Fix",$G5,$G5*(1+$H5)^(2055-$E5))))))
A6: Dieselpreis | B6: Dieselpreis | C6: EUR/L | D6: CAGR | E6: 2020 | F6: 25 | G6: 1.4 | H6: 0.02 | I6: =IF($A6="","",IF(2018<$E6,"",IF($D6="Manuell","",IF(2018>$E6+$F6,IF($D6="Fix",$G6,$G6*(1+$H6)^($F6)),IF($D6="Fix",$G6,$G6*(1+$H6)^(2018-$E6)))))) | J6: =IF($A6="","",IF(2019<$E6,"",IF($D6="Manuell","",IF(2019>$E6+$F6,IF($D6="Fix",$G6,$G6*(1+$H6)^($F6)),IF($D6="Fix",$G6,$G6*(1+$H6)^(2019-$E6)))))) | K6: =IF($A6="","",IF(2020<$E6,"",IF($D6="Manuell","",IF(2020>$E6+$F6,IF($D6="Fix",$G6,$G6*(1+$H6)^($F6)),IF($D6="Fix",$G6,$G6*(1+$H6)^(2020-$E6)))))) | L6: =IF($A6="","",IF(2021<$E6,"",IF($D6="Manuell","",IF(2021>$E6+$F6,IF($D6="Fix",$G6,$G6*(1+$H6)^($F6)),IF($D6="Fix",$G6,$G6*(1+$H6)^(2021-$E6)))))) | M6: =IF($A6="","",IF(2022<$E6,"",IF($D6="Manuell","",IF(2022>$E6+$F6,IF($D6="Fix",$G6,$G6*(1+$H6)^($F6)),IF($D6="Fix",$G6,$G6*(1+$H6)^(2022-$E6)))))) | N6: =IF($A6="","",IF(2023<$E6,"",IF($D6="Manuell","",IF(2023>$E6+$F6,IF($D6="Fix",$G6,$G6*(1+$H6)^($F6)),IF($D6="Fix",$G6,$G6*(1+$H6)^(2023-$E6)))))) | O6: =IF($A6="","",IF(2024<$E6,"",IF($D6="Manuell","",IF(2024>$E6+$F6,IF($D6="Fix",$G6,$G6*(1+$H6)^($F6)),IF($D6="Fix",$G6,$G6*(1+$H6)^(2024-$E6)))))) | P6: =IF($A6="","",IF(2025<$E6,"",IF($D6="Manuell","",IF(2025>$E6+$F6,IF($D6="Fix",$G6,$G6*(1+$H6)^($F6)),IF($D6="Fix",$G6,$G6*(1+$H6)^(2025-$E6)))))) | Q6: =IF($A6="","",IF(2026<$E6,"",IF($D6="Manuell","",IF(2026>$E6+$F6,IF($D6="Fix",$G6,$G6*(1+$H6)^($F6)),IF($D6="Fix",$G6,$G6*(1+$H6)^(2026-$E6)))))) | R6: =IF($A6="","",IF(2027<$E6,"",IF($D6="Manuell","",IF(2027>$E6+$F6,IF($D6="Fix",$G6,$G6*(1+$H6)^($F6)),IF($D6="Fix",$G6,$G6*(1+$H6)^(2027-$E6)))))) | S6: =IF($A6="","",IF(2028<$E6,"",IF($D6="Manuell","",IF(2028>$E6+$F6,IF($D6="Fix",$G6,$G6*(1+$H6)^($F6)),IF($D6="Fix",$G6,$G6*(1+$H6)^(2028-$E6)))))) | T6: =IF($A6="","",IF(2029<$E6,"",IF($D6="Manuell","",IF(2029>$E6+$F6,IF($D6="Fix",$G6,$G6*(1+$H6)^($F6)),IF($D6="Fix",$G6,$G6*(1+$H6)^(2029-$E6)))))) | U6: =IF($A6="","",IF(2030<$E6,"",IF($D6="Manuell","",IF(2030>$E6+$F6,IF($D6="Fix",$G6,$G6*(1+$H6)^($F6)),IF($D6="Fix",$G6,$G6*(1+$H6)^(2030-$E6)))))) | V6: =IF($A6="","",IF(2031<$E6,"",IF($D6="Manuell","",IF(2031>$E6+$F6,IF($D6="Fix",$G6,$G6*(1+$H6)^($F6)),IF($D6="Fix",$G6,$G6*(1+$H6)^(2031-$E6)))))) | W6: =IF($A6="","",IF(2032<$E6,"",IF($D6="Manuell","",IF(2032>$E6+$F6,IF($D6="Fix",$G6,$G6*(1+$H6)^($F6)),IF($D6="Fix",$G6,$G6*(1+$H6)^(2032-$E6)))))) | X6: =IF($A6="","",IF(2033<$E6,"",IF($D6="Manuell","",IF(2033>$E6+$F6,IF($D6="Fix",$G6,$G6*(1+$H6)^($F6)),IF($D6="Fix",$G6,$G6*(1+$H6)^(2033-$E6)))))) | Y6: =IF($A6="","",IF(2034<$E6,"",IF($D6="Manuell","",IF(2034>$E6+$F6,IF($D6="Fix",$G6,$G6*(1+$H6)^($F6)),IF($D6="Fix",$G6,$G6*(1+$H6)^(2034-$E6)))))) | Z6: =IF($A6="","",IF(2035<$E6,"",IF($D6="Manuell","",IF(2035>$E6+$F6,IF($D6="Fix",$G6,$G6*(1+$H6)^($F6)),IF($D6="Fix",$G6,$G6*(1+$H6)^(2035-$E6)))))) | AA6: =IF($A6="","",IF(2036<$E6,"",IF($D6="Manuell","",IF(2036>$E6+$F6,IF($D6="Fix",$G6,$G6*(1+$H6)^($F6)),IF($D6="Fix",$G6,$G6*(1+$H6)^(2036-$E6)))))) | AB6: =IF($A6="","",IF(2037<$E6,"",IF($D6="Manuell","",IF(2037>$E6+$F6,IF($D6="Fix",$G6,$G6*(1+$H6)^($F6)),IF($D6="Fix",$G6,$G6*(1+$H6)^(2037-$E6)))))) | AC6: =IF($A6="","",IF(2038<$E6,"",IF($D6="Manuell","",IF(2038>$E6+$F6,IF($D6="Fix",$G6,$G6*(1+$H6)^($F6)),IF($D6="Fix",$G6,$G6*(1+$H6)^(2038-$E6)))))) | AD6: =IF($A6="","",IF(2039<$E6,"",IF($D6="Manuell","",IF(2039>$E6+$F6,IF($D6="Fix",$G6,$G6*(1+$H6)^($F6)),IF($D6="Fix",$G6,$G6*(1+$H6)^(2039-$E6)))))) | AE6: =IF($A6="","",IF(2040<$E6,"",IF($D6="Manuell","",IF(2040>$E6+$F6,IF($D6="Fix",$G6,$G6*(1+$H6)^($F6)),IF($D6="Fix",$G6,$G6*(1+$H6)^(2040-$E6)))))) | AF6: =IF($A6="","",IF(2041<$E6,"",IF($D6="Manuell","",IF(2041>$E6+$F6,IF($D6="Fix",$G6,$G6*(1+$H6)^($F6)),IF($D6="Fix",$G6,$G6*(1+$H6)^(2041-$E6)))))) | AG6: =IF($A6="","",IF(2042<$E6,"",IF($D6="Manuell","",IF(2042>$E6+$F6,IF($D6="Fix",$G6,$G6*(1+$H6)^($F6)),IF($D6="Fix",$G6,$G6*(1+$H6)^(2042-$E6)))))) | AH6: =IF($A6="","",IF(2043<$E6,"",IF($D6="Manuell","",IF(2043>$E6+$F6,IF($D6="Fix",$G6,$G6*(1+$H6)^($F6)),IF($D6="Fix",$G6,$G6*(1+$H6)^(2043-$E6)))))) | AI6: =IF($A6="","",IF(2044<$E6,"",IF($D6="Manuell","",IF(2044>$E6+$F6,IF($D6="Fix",$G6,$G6*(1+$H6)^($F6)),IF($D6="Fix",$G6,$G6*(1+$H6)^(2044-$E6)))))) | AJ6: =IF($A6="","",IF(2045<$E6,"",IF($D6="Manuell","",IF(2045>$E6+$F6,IF($D6="Fix",$G6,$G6*(1+$H6)^($F6)),IF($D6="Fix",$G6,$G6*(1+$H6)^(2045-$E6)))))) | AK6: =IF($A6="","",IF(2046<$E6,"",IF($D6="Manuell","",IF(2046>$E6+$F6,IF($D6="Fix",$G6,$G6*(1+$H6)^($F6)),IF($D6="Fix",$G6,$G6*(1+$H6)^(2046-$E6)))))) | AL6: =IF($A6="","",IF(2047<$E6,"",IF($D6="Manuell","",IF(2047>$E6+$F6,IF($D6="Fix",$G6,$G6*(1+$H6)^($F6)),IF($D6="Fix",$G6,$G6*(1+$H6)^(2047-$E6)))))) | AM6: =IF($A6="","",IF(2048<$E6,"",IF($D6="Manuell","",IF(2048>$E6+$F6,IF($D6="Fix",$G6,$G6*(1+$H6)^($F6)),IF($D6="Fix",$G6,$G6*(1+$H6)^(2048-$E6)))))) | AN6: =IF($A6="","",IF(2049<$E6,"",IF($D6="Manuell","",IF(2049>$E6+$F6,IF($D6="Fix",$G6,$G6*(1+$H6)^($F6)),IF($D6="Fix",$G6,$G6*(1+$H6)^(2049-$E6)))))) | AO6: =IF($A6="","",IF(2050<$E6,"",IF($D6="Manuell","",IF(2050>$E6+$F6,IF($D6="Fix",$G6,$G6*(1+$H6)^($F6)),IF($D6="Fix",$G6,$G6*(1+$H6)^(2050-$E6)))))) | AP6: =IF($A6="","",IF(2051<$E6,"",IF($D6="Manuell","",IF(2051>$E6+$F6,IF($D6="Fix",$G6,$G6*(1+$H6)^($F6)),IF($D6="Fix",$G6,$G6*(1+$H6)^(2051-$E6)))))) | AQ6: =IF($A6="","",IF(2052<$E6,"",IF($D6="Manuell","",IF(2052>$E6+$F6,IF($D6="Fix",$G6,$G6*(1+$H6)^($F6)),IF($D6="Fix",$G6,$G6*(1+$H6)^(2052-$E6)))))) | AR6: =IF($A6="","",IF(2053<$E6,"",IF($D6="Manuell","",IF(2053>$E6+$F6,IF($D6="Fix",$G6,$G6*(1+$H6)^($F6)),IF($D6="Fix",$G6,$G6*(1+$H6)^(2053-$E6)))))) | AS6: =IF($A6="","",IF(2054<$E6,"",IF($D6="Manuell","",IF(2054>$E6+$F6,IF($D6="Fix",$G6,$G6*(1+$H6)^($F6)),IF($D6="Fix",$G6,$G6*(1+$H6)^(2054-$E6)))))) | AT6: =IF($A6="","",IF(2055<$E6,"",IF($D6="Manuell","",IF(2055>$E6+$F6,IF($D6="Fix",$G6,$G6*(1+$H6)^($F6)),IF($D6="Fix",$G6,$G6*(1+$H6)^(2055-$E6))))))
A7: Wasserpreis | B7: Wasserpreis | C7: EUR/m3 | D7: CAGR | E7: 2025 | F7: 20 | G7: 2.5 | H7: 0.02 | I7: =IF($A7="","",IF(2018<$E7,"",IF($D7="Manuell","",IF(2018>$E7+$F7,IF($D7="Fix",$G7,$G7*(1+$H7)^($F7)),IF($D7="Fix",$G7,$G7*(1+$H7)^(2018-$E7)))))) | J7: =IF($A7="","",IF(2019<$E7,"",IF($D7="Manuell","",IF(2019>$E7+$F7,IF($D7="Fix",$G7,$G7*(1+$H7)^($F7)),IF($D7="Fix",$G7,$G7*(1+$H7)^(2019-$E7)))))) | K7: =IF($A7="","",IF(2020<$E7,"",IF($D7="Manuell","",IF(2020>$E7+$F7,IF($D7="Fix",$G7,$G7*(1+$H7)^($F7)),IF($D7="Fix",$G7,$G7*(1+$H7)^(2020-$E7)))))) | L7: =IF($A7="","",IF(2021<$E7,"",IF($D7="Manuell","",IF(2021>$E7+$F7,IF($D7="Fix",$G7,$G7*(1+$H7)^($F7)),IF($D7="Fix",$G7,$G7*(1+$H7)^(2021-$E7)))))) | M7: =IF($A7="","",IF(2022<$E7,"",IF($D7="Manuell","",IF(2022>$E7+$F7,IF($D7="Fix",$G7,$G7*(1+$H7)^($F7)),IF($D7="Fix",$G7,$G7*(1+$H7)^(2022-$E7)))))) | N7: =IF($A7="","",IF(2023<$E7,"",IF($D7="Manuell","",IF(2023>$E7+$F7,IF($D7="Fix",$G7,$G7*(1+$H7)^($F7)),IF($D7="Fix",$G7,$G7*(1+$H7)^(2023-$E7)))))) | O7: =IF($A7="","",IF(2024<$E7,"",IF($D7="Manuell","",IF(2024>$E7+$F7,IF($D7="Fix",$G7,$G7*(1+$H7)^($F7)),IF($D7="Fix",$G7,$G7*(1+$H7)^(2024-$E7)))))) | P7: =IF($A7="","",IF(2025<$E7,"",IF($D7="Manuell","",IF(2025>$E7+$F7,IF($D7="Fix",$G7,$G7*(1+$H7)^($F7)),IF($D7="Fix",$G7,$G7*(1+$H7)^(2025-$E7)))))) | Q7: =IF($A7="","",IF(2026<$E7,"",IF($D7="Manuell","",IF(2026>$E7+$F7,IF($D7="Fix",$G7,$G7*(1+$H7)^($F7)),IF($D7="Fix",$G7,$G7*(1+$H7)^(2026-$E7)))))) | R7: =IF($A7="","",IF(2027<$E7,"",IF($D7="Manuell","",IF(2027>$E7+$F7,IF($D7="Fix",$G7,$G7*(1+$H7)^($F7)),IF($D7="Fix",$G7,$G7*(1+$H7)^(2027-$E7)))))) | S7: =IF($A7="","",IF(2028<$E7,"",IF($D7="Manuell","",IF(2028>$E7+$F7,IF($D7="Fix",$G7,$G7*(1+$H7)^($F7)),IF($D7="Fix",$G7,$G7*(1+$H7)^(2028-$E7)))))) | T7: =IF($A7="","",IF(2029<$E7,"",IF($D7="Manuell","",IF(2029>$E7+$F7,IF($D7="Fix",$G7,$G7*(1+$H7)^($F7)),IF($D7="Fix",$G7,$G7*(1+$H7)^(2029-$E7)))))) | U7: =IF($A7="","",IF(2030<$E7,"",IF($D7="Manuell","",IF(2030>$E7+$F7,IF($D7="Fix",$G7,$G7*(1+$H7)^($F7)),IF($D7="Fix",$G7,$G7*(1+$H7)^(2030-$E7)))))) | V7: =IF($A7="","",IF(2031<$E7,"",IF($D7="Manuell","",IF(2031>$E7+$F7,IF($D7="Fix",$G7,$G7*(1+$H7)^($F7)),IF($D7="Fix",$G7,$G7*(1+$H7)^(2031-$E7)))))) | W7: =IF($A7="","",IF(2032<$E7,"",IF($D7="Manuell","",IF(2032>$E7+$F7,IF($D7="Fix",$G7,$G7*(1+$H7)^($F7)),IF($D7="Fix",$G7,$G7*(1+$H7)^(2032-$E7)))))) | X7: =IF($A7="","",IF(2033<$E7,"",IF($D7="Manuell","",IF(2033>$E7+$F7,IF($D7="Fix",$G7,$G7*(1+$H7)^($F7)),IF($D7="Fix",$G7,$G7*(1+$H7)^(2033-$E7)))))) | Y7: =IF($A7="","",IF(2034<$E7,"",IF($D7="Manuell","",IF(2034>$E7+$F7,IF($D7="Fix",$G7,$G7*(1+$H7)^($F7)),IF($D7="Fix",$G7,$G7*(1+$H7)^(2034-$E7)))))) | Z7: =IF($A7="","",IF(2035<$E7,"",IF($D7="Manuell","",IF(2035>$E7+$F7,IF($D7="Fix",$G7,$G7*(1+$H7)^($F7)),IF($D7="Fix",$G7,$G7*(1+$H7)^(2035-$E7)))))) | AA7: =IF($A7="","",IF(2036<$E7,"",IF($D7="Manuell","",IF(2036>$E7+$F7,IF($D7="Fix",$G7,$G7*(1+$H7)^($F7)),IF($D7="Fix",$G7,$G7*(1+$H7)^(2036-$E7)))))) | AB7: =IF($A7="","",IF(2037<$E7,"",IF($D7="Manuell","",IF(2037>$E7+$F7,IF($D7="Fix",$G7,$G7*(1+$H7)^($F7)),IF($D7="Fix",$G7,$G7*(1+$H7)^(2037-$E7)))))) | AC7: =IF($A7="","",IF(2038<$E7,"",IF($D7="Manuell","",IF(2038>$E7+$F7,IF($D7="Fix",$G7,$G7*(1+$H7)^($F7)),IF($D7="Fix",$G7,$G7*(1+$H7)^(2038-$E7)))))) | AD7: =IF($A7="","",IF(2039<$E7,"",IF($D7="Manuell","",IF(2039>$E7+$F7,IF($D7="Fix",$G7,$G7*(1+$H7)^($F7)),IF($D7="Fix",$G7,$G7*(1+$H7)^(2039-$E7)))))) | AE7: =IF($A7="","",IF(2040<$E7,"",IF($D7="Manuell","",IF(2040>$E7+$F7,IF($D7="Fix",$G7,$G7*(1+$H7)^($F7)),IF($D7="Fix",$G7,$G7*(1+$H7)^(2040-$E7)))))) | AF7: =IF($A7="","",IF(2041<$E7,"",IF($D7="Manuell","",IF(2041>$E7+$F7,IF($D7="Fix",$G7,$G7*(1+$H7)^($F7)),IF($D7="Fix",$G7,$G7*(1+$H7)^(2041-$E7)))))) | AG7: =IF($A7="","",IF(2042<$E7,"",IF($D7="Manuell","",IF(2042>$E7+$F7,IF($D7="Fix",$G7,$G7*(1+$H7)^($F7)),IF($D7="Fix",$G7,$G7*(1+$H7)^(2042-$E7)))))) | AH7: =IF($A7="","",IF(2043<$E7,"",IF($D7="Manuell","",IF(2043>$E7+$F7,IF($D7="Fix",$G7,$G7*(1+$H7)^($F7)),IF($D7="Fix",$G7,$G7*(1+$H7)^(2043-$E7)))))) | AI7: =IF($A7="","",IF(2044<$E7,"",IF($D7="Manuell","",IF(2044>$E7+$F7,IF($D7="Fix",$G7,$G7*(1+$H7)^($F7)),IF($D7="Fix",$G7,$G7*(1+$H7)^(2044-$E7)))))) | AJ7: =IF($A7="","",IF(2045<$E7,"",IF($D7="Manuell","",IF(2045>$E7+$F7,IF($D7="Fix",$G7,$G7*(1+$H7)^($F7)),IF($D7="Fix",$G7,$G7*(1+$H7)^(2045-$E7)))))) | AK7: =IF($A7="","",IF(2046<$E7,"",IF($D7="Manuell","",IF(2046>$E7+$F7,IF($D7="Fix",$G7,$G7*(1+$H7)^($F7)),IF($D7="Fix",$G7,$G7*(1+$H7)^(2046-$E7)))))) | AL7: =IF($A7="","",IF(2047<$E7,"",IF($D7="Manuell","",IF(2047>$E7+$F7,IF($D7="Fix",$G7,$G7*(1+$H7)^($F7)),IF($D7="Fix",$G7,$G7*(1+$H7)^(2047-$E7)))))) | AM7: =IF($A7="","",IF(2048<$E7,"",IF($D7="Manuell","",IF(2048>$E7+$F7,IF($D7="Fix",$G7,$G7*(1+$H7)^($F7)),IF($D7="Fix",$G7,$G7*(1+$H7)^(2048-$E7)))))) | AN7: =IF($A7="","",IF(2049<$E7,"",IF($D7="Manuell","",IF(2049>$E7+$F7,IF($D7="Fix",$G7,$G7*(1+$H7)^($F7)),IF($D7="Fix",$G7,$G7*(1+$H7)^(2049-$E7)))))) | AO7: =IF($A7="","",IF(2050<$E7,"",IF($D7="Manuell","",IF(2050>$E7+$F7,IF($D7="Fix",$G7,$G7*(1+$H7)^($F7)),IF($D7="Fix",$G7,$G7*(1+$H7)^(2050-$E7)))))) | AP7: =IF($A7="","",IF(2051<$E7,"",IF($D7="Manuell","",IF(2051>$E7+$F7,IF($D7="Fix",$G7,$G7*(1+$H7)^($F7)),IF($D7="Fix",$G7,$G7*(1+$H7)^(2051-$E7)))))) | AQ7: =IF($A7="","",IF(2052<$E7,"",IF($D7="Manuell","",IF(2052>$E7+$F7,IF($D7="Fix",$G7,$G7*(1+$H7)^($F7)),IF($D7="Fix",$G7,$G7*(1+$H7)^(2052-$E7)))))) | AR7: =IF($A7="","",IF(2053<$E7,"",IF($D7="Manuell","",IF(2053>$E7+$F7,IF($D7="Fix",$G7,$G7*(1+$H7)^($F7)),IF($D7="Fix",$G7,$G7*(1+$H7)^(2053-$E7)))))) | AS7: =IF($A7="","",IF(2054<$E7,"",IF($D7="Manuell","",IF(2054>$E7+$F7,IF($D7="Fix",$G7,$G7*(1+$H7)^($F7)),IF($D7="Fix",$G7,$G7*(1+$H7)^(2054-$E7)))))) | AT7: =IF($A7="","",IF(2055<$E7,"",IF($D7="Manuell","",IF(2055>$E7+$F7,IF($D7="Fix",$G7,$G7*(1+$H7)^($F7)),IF($D7="Fix",$G7,$G7*(1+$H7)^(2055-$E7))))))
A8: Entsorgungspreis | B8: Entsorgung | C8: EUR/t | D8: CAGR | E8: 2025 | F8: 20 | G8: 150 | H8: 0.02 | I8: =IF($A8="","",IF(2018<$E8,"",IF($D8="Manuell","",IF(2018>$E8+$F8,IF($D8="Fix",$G8,$G8*(1+$H8)^($F8)),IF($D8="Fix",$G8,$G8*(1+$H8)^(2018-$E8)))))) | J8: =IF($A8="","",IF(2019<$E8,"",IF($D8="Manuell","",IF(2019>$E8+$F8,IF($D8="Fix",$G8,$G8*(1+$H8)^($F8)),IF($D8="Fix",$G8,$G8*(1+$H8)^(2019-$E8)))))) | K8: =IF($A8="","",IF(2020<$E8,"",IF($D8="Manuell","",IF(2020>$E8+$F8,IF($D8="Fix",$G8,$G8*(1+$H8)^($F8)),IF($D8="Fix",$G8,$G8*(1+$H8)^(2020-$E8)))))) | L8: =IF($A8="","",IF(2021<$E8,"",IF($D8="Manuell","",IF(2021>$E8+$F8,IF($D8="Fix",$G8,$G8*(1+$H8)^($F8)),IF($D8="Fix",$G8,$G8*(1+$H8)^(2021-$E8)))))) | M8: =IF($A8="","",IF(2022<$E8,"",IF($D8="Manuell","",IF(2022>$E8+$F8,IF($D8="Fix",$G8,$G8*(1+$H8)^($F8)),IF($D8="Fix",$G8,$G8*(1+$H8)^(2022-$E8)))))) | N8: =IF($A8="","",IF(2023<$E8,"",IF($D8="Manuell","",IF(2023>$E8+$F8,IF($D8="Fix",$G8,$G8*(1+$H8)^($F8)),IF($D8="Fix",$G8,$G8*(1+$H8)^(2023-$E8)))))) | O8: =IF($A8="","",IF(2024<$E8,"",IF($D8="Manuell","",IF(2024>$E8+$F8,IF($D8="Fix",$G8,$G8*(1+$H8)^($F8)),IF($D8="Fix",$G8,$G8*(1+$H8)^(2024-$E8)))))) | P8: =IF($A8="","",IF(2025<$E8,"",IF($D8="Manuell","",IF(2025>$E8+$F8,IF($D8="Fix",$G8,$G8*(1+$H8)^($F8)),IF($D8="Fix",$G8,$G8*(1+$H8)^(2025-$E8)))))) | Q8: =IF($A8="","",IF(2026<$E8,"",IF($D8="Manuell","",IF(2026>$E8+$F8,IF($D8="Fix",$G8,$G8*(1+$H8)^($F8)),IF($D8="Fix",$G8,$G8*(1+$H8)^(2026-$E8)))))) | R8: =IF($A8="","",IF(2027<$E8,"",IF($D8="Manuell","",IF(2027>$E8+$F8,IF($D8="Fix",$G8,$G8*(1+$H8)^($F8)),IF($D8="Fix",$G8,$G8*(1+$H8)^(2027-$E8)))))) | S8: =IF($A8="","",IF(2028<$E8,"",IF($D8="Manuell","",IF(2028>$E8+$F8,IF($D8="Fix",$G8,$G8*(1+$H8)^($F8)),IF($D8="Fix",$G8,$G8*(1+$H8)^(2028-$E8)))))) | T8: =IF($A8="","",IF(2029<$E8,"",IF($D8="Manuell","",IF(2029>$E8+$F8,IF($D8="Fix",$G8,$G8*(1+$H8)^($F8)),IF($D8="Fix",$G8,$G8*(1+$H8)^(2029-$E8)))))) | U8: =IF($A8="","",IF(2030<$E8,"",IF($D8="Manuell","",IF(2030>$E8+$F8,IF($D8="Fix",$G8,$G8*(1+$H8)^($F8)),IF($D8="Fix",$G8,$G8*(1+$H8)^(2030-$E8)))))) | V8: =IF($A8="","",IF(2031<$E8,"",IF($D8="Manuell","",IF(2031>$E8+$F8,IF($D8="Fix",$G8,$G8*(1+$H8)^($F8)),IF($D8="Fix",$G8,$G8*(1+$H8)^(2031-$E8)))))) | W8: =IF($A8="","",IF(2032<$E8,"",IF($D8="Manuell","",IF(2032>$E8+$F8,IF($D8="Fix",$G8,$G8*(1+$H8)^($F8)),IF($D8="Fix",$G8,$G8*(1+$H8)^(2032-$E8)))))) | X8: =IF($A8="","",IF(2033<$E8,"",IF($D8="Manuell","",IF(2033>$E8+$F8,IF($D8="Fix",$G8,$G8*(1+$H8)^($F8)),IF($D8="Fix",$G8,$G8*(1+$H8)^(2033-$E8)))))) | Y8: =IF($A8="","",IF(2034<$E8,"",IF($D8="Manuell","",IF(2034>$E8+$F8,IF($D8="Fix",$G8,$G8*(1+$H8)^($F8)),IF($D8="Fix",$G8,$G8*(1+$H8)^(2034-$E8)))))) | Z8: =IF($A8="","",IF(2035<$E8,"",IF($D8="Manuell","",IF(2035>$E8+$F8,IF($D8="Fix",$G8,$G8*(1+$H8)^($F8)),IF($D8="Fix",$G8,$G8*(1+$H8)^(2035-$E8)))))) | AA8: =IF($A8="","",IF(2036<$E8,"",IF($D8="Manuell","",IF(2036>$E8+$F8,IF($D8="Fix",$G8,$G8*(1+$H8)^($F8)),IF($D8="Fix",$G8,$G8*(1+$H8)^(2036-$E8)))))) | AB8: =IF($A8="","",IF(2037<$E8,"",IF($D8="Manuell","",IF(2037>$E8+$F8,IF($D8="Fix",$G8,$G8*(1+$H8)^($F8)),IF($D8="Fix",$G8,$G8*(1+$H8)^(2037-$E8)))))) | AC8: =IF($A8="","",IF(2038<$E8,"",IF($D8="Manuell","",IF(2038>$E8+$F8,IF($D8="Fix",$G8,$G8*(1+$H8)^($F8)),IF($D8="Fix",$G8,$G8*(1+$H8)^(2038-$E8)))))) | AD8: =IF($A8="","",IF(2039<$E8,"",IF($D8="Manuell","",IF(2039>$E8+$F8,IF($D8="Fix",$G8,$G8*(1+$H8)^($F8)),IF($D8="Fix",$G8,$G8*(1+$H8)^(2039-$E8)))))) | AE8: =IF($A8="","",IF(2040<$E8,"",IF($D8="Manuell","",IF(2040>$E8+$F8,IF($D8="Fix",$G8,$G8*(1+$H8)^($F8)),IF($D8="Fix",$G8,$G8*(1+$H8)^(2040-$E8)))))) | AF8: =IF($A8="","",IF(2041<$E8,"",IF($D8="Manuell","",IF(2041>$E8+$F8,IF($D8="Fix",$G8,$G8*(1+$H8)^($F8)),IF($D8="Fix",$G8,$G8*(1+$H8)^(2041-$E8)))))) | AG8: =IF($A8="","",IF(2042<$E8,"",IF($D8="Manuell","",IF(2042>$E8+$F8,IF($D8="Fix",$G8,$G8*(1+$H8)^($F8)),IF($D8="Fix",$G8,$G8*(1+$H8)^(2042-$E8)))))) | AH8: =IF($A8="","",IF(2043<$E8,"",IF($D8="Manuell","",IF(2043>$E8+$F8,IF($D8="Fix",$G8,$G8*(1+$H8)^($F8)),IF($D8="Fix",$G8,$G8*(1+$H8)^(2043-$E8)))))) | AI8: =IF($A8="","",IF(2044<$E8,"",IF($D8="Manuell","",IF(2044>$E8+$F8,IF($D8="Fix",$G8,$G8*(1+$H8)^($F8)),IF($D8="Fix",$G8,$G8*(1+$H8)^(2044-$E8)))))) | AJ8: =IF($A8="","",IF(2045<$E8,"",IF($D8="Manuell","",IF(2045>$E8+$F8,IF($D8="Fix",$G8,$G8*(1+$H8)^($F8)),IF($D8="Fix",$G8,$G8*(1+$H8)^(2045-$E8)))))) | AK8: =IF($A8="","",IF(2046<$E8,"",IF($D8="Manuell","",IF(2046>$E8+$F8,IF($D8="Fix",$G8,$G8*(1+$H8)^($F8)),IF($D8="Fix",$G8,$G8*(1+$H8)^(2046-$E8)))))) | AL8: =IF($A8="","",IF(2047<$E8,"",IF($D8="Manuell","",IF(2047>$E8+$F8,IF($D8="Fix",$G8,$G8*(1+$H8)^($F8)),IF($D8="Fix",$G8,$G8*(1+$H8)^(2047-$E8)))))) | AM8: =IF($A8="","",IF(2048<$E8,"",IF($D8="Manuell","",IF(2048>$E8+$F8,IF($D8="Fix",$G8,$G8*(1+$H8)^($F8)),IF($D8="Fix",$G8,$G8*(1+$H8)^(2048-$E8)))))) | AN8: =IF($A8="","",IF(2049<$E8,"",IF($D8="Manuell","",IF(2049>$E8+$F8,IF($D8="Fix",$G8,$G8*(1+$H8)^($F8)),IF($D8="Fix",$G8,$G8*(1+$H8)^(2049-$E8)))))) | AO8: =IF($A8="","",IF(2050<$E8,"",IF($D8="Manuell","",IF(2050>$E8+$F8,IF($D8="Fix",$G8,$G8*(1+$H8)^($F8)),IF($D8="Fix",$G8,$G8*(1+$H8)^(2050-$E8)))))) | AP8: =IF($A8="","",IF(2051<$E8,"",IF($D8="Manuell","",IF(2051>$E8+$F8,IF($D8="Fix",$G8,$G8*(1+$H8)^($F8)),IF($D8="Fix",$G8,$G8*(1+$H8)^(2051-$E8)))))) | AQ8: =IF($A8="","",IF(2052<$E8,"",IF($D8="Manuell","",IF(2052>$E8+$F8,IF($D8="Fix",$G8,$G8*(1+$H8)^($F8)),IF($D8="Fix",$G8,$G8*(1+$H8)^(2052-$E8)))))) | AR8: =IF($A8="","",IF(2053<$E8,"",IF($D8="Manuell","",IF(2053>$E8+$F8,IF($D8="Fix",$G8,$G8*(1+$H8)^($F8)),IF($D8="Fix",$G8,$G8*(1+$H8)^(2053-$E8)))))) | AS8: =IF($A8="","",IF(2054<$E8,"",IF($D8="Manuell","",IF(2054>$E8+$F8,IF($D8="Fix",$G8,$G8*(1+$H8)^($F8)),IF($D8="Fix",$G8,$G8*(1+$H8)^(2054-$E8)))))) | AT8: =IF($A8="","",IF(2055<$E8,"",IF($D8="Manuell","",IF(2055>$E8+$F8,IF($D8="Fix",$G8,$G8*(1+$H8)^($F8)),IF($D8="Fix",$G8,$G8*(1+$H8)^(2055-$E8))))))
A9: Plastikpreis | B9: Kunststoff | C9: EUR/kg | D9: CAGR | E9: 2020 | F9: 20 | G9: 1.8 | H9: 0.01 | I9: =IF($A9="","",IF(2018<$E9,"",IF($D9="Manuell","",IF(2018>$E9+$F9,IF($D9="Fix",$G9,$G9*(1+$H9)^($F9)),IF($D9="Fix",$G9,$G9*(1+$H9)^(2018-$E9)))))) | J9: =IF($A9="","",IF(2019<$E9,"",IF($D9="Manuell","",IF(2019>$E9+$F9,IF($D9="Fix",$G9,$G9*(1+$H9)^($F9)),IF($D9="Fix",$G9,$G9*(1+$H9)^(2019-$E9)))))) | K9: =IF($A9="","",IF(2020<$E9,"",IF($D9="Manuell","",IF(2020>$E9+$F9,IF($D9="Fix",$G9,$G9*(1+$H9)^($F9)),IF($D9="Fix",$G9,$G9*(1+$H9)^(2020-$E9)))))) | L9: =IF($A9="","",IF(2021<$E9,"",IF($D9="Manuell","",IF(2021>$E9+$F9,IF($D9="Fix",$G9,$G9*(1+$H9)^($F9)),IF($D9="Fix",$G9,$G9*(1+$H9)^(2021-$E9)))))) | M9: =IF($A9="","",IF(2022<$E9,"",IF($D9="Manuell","",IF(2022>$E9+$F9,IF($D9="Fix",$G9,$G9*(1+$H9)^($F9)),IF($D9="Fix",$G9,$G9*(1+$H9)^(2022-$E9)))))) | N9: =IF($A9="","",IF(2023<$E9,"",IF($D9="Manuell","",IF(2023>$E9+$F9,IF($D9="Fix",$G9,$G9*(1+$H9)^($F9)),IF($D9="Fix",$G9,$G9*(1+$H9)^(2023-$E9)))))) | O9: =IF($A9="","",IF(2024<$E9,"",IF($D9="Manuell","",IF(2024>$E9+$F9,IF($D9="Fix",$G9,$G9*(1+$H9)^($F9)),IF($D9="Fix",$G9,$G9*(1+$H9)^(2024-$E9)))))) | P9: =IF($A9="","",IF(2025<$E9,"",IF($D9="Manuell","",IF(2025>$E9+$F9,IF($D9="Fix",$G9,$G9*(1+$H9)^($F9)),IF($D9="Fix",$G9,$G9*(1+$H9)^(2025-$E9)))))) | Q9: =IF($A9="","",IF(2026<$E9,"",IF($D9="Manuell","",IF(2026>$E9+$F9,IF($D9="Fix",$G9,$G9*(1+$H9)^($F9)),IF($D9="Fix",$G9,$G9*(1+$H9)^(2026-$E9)))))) | R9: =IF($A9="","",IF(2027<$E9,"",IF($D9="Manuell","",IF(2027>$E9+$F9,IF($D9="Fix",$G9,$G9*(1+$H9)^($F9)),IF($D9="Fix",$G9,$G9*(1+$H9)^(2027-$E9)))))) | S9: =IF($A9="","",IF(2028<$E9,"",IF($D9="Manuell","",IF(2028>$E9+$F9,IF($D9="Fix",$G9,$G9*(1+$H9)^($F9)),IF($D9="Fix",$G9,$G9*(1+$H9)^(2028-$E9)))))) | T9: =IF($A9="","",IF(2029<$E9,"",IF($D9="Manuell","",IF(2029>$E9+$F9,IF($D9="Fix",$G9,$G9*(1+$H9)^($F9)),IF($D9="Fix",$G9,$G9*(1+$H9)^(2029-$E9)))))) | U9: =IF($A9="","",IF(2030<$E9,"",IF($D9="Manuell","",IF(2030>$E9+$F9,IF($D9="Fix",$G9,$G9*(1+$H9)^($F9)),IF($D9="Fix",$G9,$G9*(1+$H9)^(2030-$E9)))))) | V9: =IF($A9="","",IF(2031<$E9,"",IF($D9="Manuell","",IF(2031>$E9+$F9,IF($D9="Fix",$G9,$G9*(1+$H9)^($F9)),IF($D9="Fix",$G9,$G9*(1+$H9)^(2031-$E9)))))) | W9: =IF($A9="","",IF(2032<$E9,"",IF($D9="Manuell","",IF(2032>$E9+$F9,IF($D9="Fix",$G9,$G9*(1+$H9)^($F9)),IF($D9="Fix",$G9,$G9*(1+$H9)^(2032-$E9)))))) | X9: =IF($A9="","",IF(2033<$E9,"",IF($D9="Manuell","",IF(2033>$E9+$F9,IF($D9="Fix",$G9,$G9*(1+$H9)^($F9)),IF($D9="Fix",$G9,$G9*(1+$H9)^(2033-$E9)))))) | Y9: =IF($A9="","",IF(2034<$E9,"",IF($D9="Manuell","",IF(2034>$E9+$F9,IF($D9="Fix",$G9,$G9*(1+$H9)^($F9)),IF($D9="Fix",$G9,$G9*(1+$H9)^(2034-$E9)))))) | Z9: =IF($A9="","",IF(2035<$E9,"",IF($D9="Manuell","",IF(2035>$E9+$F9,IF($D9="Fix",$G9,$G9*(1+$H9)^($F9)),IF($D9="Fix",$G9,$G9*(1+$H9)^(2035-$E9)))))) | AA9: =IF($A9="","",IF(2036<$E9,"",IF($D9="Manuell","",IF(2036>$E9+$F9,IF($D9="Fix",$G9,$G9*(1+$H9)^($F9)),IF($D9="Fix",$G9,$G9*(1+$H9)^(2036-$E9)))))) | AB9: =IF($A9="","",IF(2037<$E9,"",IF($D9="Manuell","",IF(2037>$E9+$F9,IF($D9="Fix",$G9,$G9*(1+$H9)^($F9)),IF($D9="Fix",$G9,$G9*(1+$H9)^(2037-$E9)))))) | AC9: =IF($A9="","",IF(2038<$E9,"",IF($D9="Manuell","",IF(2038>$E9+$F9,IF($D9="Fix",$G9,$G9*(1+$H9)^($F9)),IF($D9="Fix",$G9,$G9*(1+$H9)^(2038-$E9)))))) | AD9: =IF($A9="","",IF(2039<$E9,"",IF($D9="Manuell","",IF(2039>$E9+$F9,IF($D9="Fix",$G9,$G9*(1+$H9)^($F9)),IF($D9="Fix",$G9,$G9*(1+$H9)^(2039-$E9)))))) | AE9: =IF($A9="","",IF(2040<$E9,"",IF($D9="Manuell","",IF(2040>$E9+$F9,IF($D9="Fix",$G9,$G9*(1+$H9)^($F9)),IF($D9="Fix",$G9,$G9*(1+$H9)^(2040-$E9)))))) | AF9: =IF($A9="","",IF(2041<$E9,"",IF($D9="Manuell","",IF(2041>$E9+$F9,IF($D9="Fix",$G9,$G9*(1+$H9)^($F9)),IF($D9="Fix",$G9,$G9*(1+$H9)^(2041-$E9)))))) | AG9: =IF($A9="","",IF(2042<$E9,"",IF($D9="Manuell","",IF(2042>$E9+$F9,IF($D9="Fix",$G9,$G9*(1+$H9)^($F9)),IF($D9="Fix",$G9,$G9*(1+$H9)^(2042-$E9)))))) | AH9: =IF($A9="","",IF(2043<$E9,"",IF($D9="Manuell","",IF(2043>$E9+$F9,IF($D9="Fix",$G9,$G9*(1+$H9)^($F9)),IF($D9="Fix",$G9,$G9*(1+$H9)^(2043-$E9)))))) | AI9: =IF($A9="","",IF(2044<$E9,"",IF($D9="Manuell","",IF(2044>$E9+$F9,IF($D9="Fix",$G9,$G9*(1+$H9)^($F9)),IF($D9="Fix",$G9,$G9*(1+$H9)^(2044-$E9)))))) | AJ9: =IF($A9="","",IF(2045<$E9,"",IF($D9="Manuell","",IF(2045>$E9+$F9,IF($D9="Fix",$G9,$G9*(1+$H9)^($F9)),IF($D9="Fix",$G9,$G9*(1+$H9)^(2045-$E9)))))) | AK9: =IF($A9="","",IF(2046<$E9,"",IF($D9="Manuell","",IF(2046>$E9+$F9,IF($D9="Fix",$G9,$G9*(1+$H9)^($F9)),IF($D9="Fix",$G9,$G9*(1+$H9)^(2046-$E9)))))) | AL9: =IF($A9="","",IF(2047<$E9,"",IF($D9="Manuell","",IF(2047>$E9+$F9,IF($D9="Fix",$G9,$G9*(1+$H9)^($F9)),IF($D9="Fix",$G9,$G9*(1+$H9)^(2047-$E9)))))) | AM9: =IF($A9="","",IF(2048<$E9,"",IF($D9="Manuell","",IF(2048>$E9+$F9,IF($D9="Fix",$G9,$G9*(1+$H9)^($F9)),IF($D9="Fix",$G9,$G9*(1+$H9)^(2048-$E9)))))) | AN9: =IF($A9="","",IF(2049<$E9,"",IF($D9="Manuell","",IF(2049>$E9+$F9,IF($D9="Fix",$G9,$G9*(1+$H9)^($F9)),IF($D9="Fix",$G9,$G9*(1+$H9)^(2049-$E9)))))) | AO9: =IF($A9="","",IF(2050<$E9,"",IF($D9="Manuell","",IF(2050>$E9+$F9,IF($D9="Fix",$G9,$G9*(1+$H9)^($F9)),IF($D9="Fix",$G9,$G9*(1+$H9)^(2050-$E9)))))) | AP9: =IF($A9="","",IF(2051<$E9,"",IF($D9="Manuell","",IF(2051>$E9+$F9,IF($D9="Fix",$G9,$G9*(1+$H9)^($F9)),IF($D9="Fix",$G9,$G9*(1+$H9)^(2051-$E9)))))) | AQ9: =IF($A9="","",IF(2052<$E9,"",IF($D9="Manuell","",IF(2052>$E9+$F9,IF($D9="Fix",$G9,$G9*(1+$H9)^($F9)),IF($D9="Fix",$G9,$G9*(1+$H9)^(2052-$E9)))))) | AR9: =IF($A9="","",IF(2053<$E9,"",IF($D9="Manuell","",IF(2053>$E9+$F9,IF($D9="Fix",$G9,$G9*(1+$H9)^($F9)),IF($D9="Fix",$G9,$G9*(1+$H9)^(2053-$E9)))))) | AS9: =IF($A9="","",IF(2054<$E9,"",IF($D9="Manuell","",IF(2054>$E9+$F9,IF($D9="Fix",$G9,$G9*(1+$H9)^($F9)),IF($D9="Fix",$G9,$G9*(1+$H9)^(2054-$E9)))))) | AT9: =IF($A9="","",IF(2055<$E9,"",IF($D9="Manuell","",IF(2055>$E9+$F9,IF($D9="Fix",$G9,$G9*(1+$H9)^($F9)),IF($D9="Fix",$G9,$G9*(1+$H9)^(2055-$E9))))))
I10: =IF($A10="","",IF(2018<$E10,"",IF($D10="Manuell","",IF(2018>$E10+$F10,IF($D10="Fix",$G10,$G10*(1+$H10)^($F10)),IF($D10="Fix",$G10,$G10*(1+$H10)^(2018-$E10)))))) | J10: =IF($A10="","",IF(2019<$E10,"",IF($D10="Manuell","",IF(2019>$E10+$F10,IF($D10="Fix",$G10,$G10*(1+$H10)^($F10)),IF($D10="Fix",$G10,$G10*(1+$H10)^(2019-$E10)))))) | K10: =IF($A10="","",IF(2020<$E10,"",IF($D10="Manuell","",IF(2020>$E10+$F10,IF($D10="Fix",$G10,$G10*(1+$H10)^($F10)),IF($D10="Fix",$G10,$G10*(1+$H10)^(2020-$E10)))))) | L10: =IF($A10="","",IF(2021<$E10,"",IF($D10="Manuell","",IF(2021>$E10+$F10,IF($D10="Fix",$G10,$G10*(1+$H10)^($F10)),IF($D10="Fix",$G10,$G10*(1+$H10)^(2021-$E10)))))) | M10: =IF($A10="","",IF(2022<$E10,"",IF($D10="Manuell","",IF(2022>$E10+$F10,IF($D10="Fix",$G10,$G10*(1+$H10)^($F10)),IF($D10="Fix",$G10,$G10*(1+$H10)^(2022-$E10)))))) | N10: =IF($A10="","",IF(2023<$E10,"",IF($D10="Manuell","",IF(2023>$E10+$F10,IF($D10="Fix",$G10,$G10*(1+$H10)^($F10)),IF($D10="Fix",$G10,$G10*(1+$H10)^(2023-$E10)))))) | O10: =IF($A10="","",IF(2024<$E10,"",IF($D10="Manuell","",IF(2024>$E10+$F10,IF($D10="Fix",$G10,$G10*(1+$H10)^($F10)),IF($D10="Fix",$G10,$G10*(1+$H10)^(2024-$E10)))))) | P10: =IF($A10="","",IF(2025<$E10,"",IF($D10="Manuell","",IF(2025>$E10+$F10,IF($D10="Fix",$G10,$G10*(1+$H10)^($F10)),IF($D10="Fix",$G10,$G10*(1+$H10)^(2025-$E10)))))) | Q10: =IF($A10="","",IF(2026<$E10,"",IF($D10="Manuell","",IF(2026>$E10+$F10,IF($D10="Fix",$G10,$G10*(1+$H10)^($F10)),IF($D10="Fix",$G10,$G10*(1+$H10)^(2026-$E10)))))) | R10: =IF($A10="","",IF(2027<$E10,"",IF($D10="Manuell","",IF(2027>$E10+$F10,IF($D10="Fix",$G10,$G10*(1+$H10)^($F10)),IF($D10="Fix",$G10,$G10*(1+$H10)^(2027-$E10)))))) | S10: =IF($A10="","",IF(2028<$E10,"",IF($D10="Manuell","",IF(2028>$E10+$F10,IF($D10="Fix",$G10,$G10*(1+$H10)^($F10)),IF($D10="Fix",$G10,$G10*(1+$H10)^(2028-$E10)))))) | T10: =IF($A10="","",IF(2029<$E10,"",IF($D10="Manuell","",IF(2029>$E10+$F10,IF($D10="Fix",$G10,$G10*(1+$H10)^($F10)),IF($D10="Fix",$G10,$G10*(1+$H10)^(2029-$E10)))))) | U10: =IF($A10="","",IF(2030<$E10,"",IF($D10="Manuell","",IF(2030>$E10+$F10,IF($D10="Fix",$G10,$G10*(1+$H10)^($F10)),IF($D10="Fix",$G10,$G10*(1+$H10)^(2030-$E10)))))) | V10: =IF($A10="","",IF(2031<$E10,"",IF($D10="Manuell","",IF(2031>$E10+$F10,IF($D10="Fix",$G10,$G10*(1+$H10)^($F10)),IF($D10="Fix",$G10,$G10*(1+$H10)^(2031-$E10)))))) | W10: =IF($A10="","",IF(2032<$E10,"",IF($D10="Manuell","",IF(2032>$E10+$F10,IF($D10="Fix",$G10,$G10*(1+$H10)^($F10)),IF($D10="Fix",$G10,$G10*(1+$H10)^(2032-$E10)))))) | X10: =IF($A10="","",IF(2033<$E10,"",IF($D10="Manuell","",IF(2033>$E10+$F10,IF($D10="Fix",$G10,$G10*(1+$H10)^($F10)),IF($D10="Fix",$G10,$G10*(1+$H10)^(2033-$E10)))))) | Y10: =IF($A10="","",IF(2034<$E10,"",IF($D10="Manuell","",IF(2034>$E10+$F10,IF($D10="Fix",$G10,$G10*(1+$H10)^($F10)),IF($D10="Fix",$G10,$G10*(1+$H10)^(2034-$E10)))))) | Z10: =IF($A10="","",IF(2035<$E10,"",IF($D10="Manuell","",IF(2035>$E10+$F10,IF($D10="Fix",$G10,$G10*(1+$H10)^($F10)),IF($D10="Fix",$G10,$G10*(1+$H10)^(2035-$E10)))))) | AA10: =IF($A10="","",IF(2036<$E10,"",IF($D10="Manuell","",IF(2036>$E10+$F10,IF($D10="Fix",$G10,$G10*(1+$H10)^($F10)),IF($D10="Fix",$G10,$G10*(1+$H10)^(2036-$E10)))))) | AB10: =IF($A10="","",IF(2037<$E10,"",IF($D10="Manuell","",IF(2037>$E10+$F10,IF($D10="Fix",$G10,$G10*(1+$H10)^($F10)),IF($D10="Fix",$G10,$G10*(1+$H10)^(2037-$E10)))))) | AC10: =IF($A10="","",IF(2038<$E10,"",IF($D10="Manuell","",IF(2038>$E10+$F10,IF($D10="Fix",$G10,$G10*(1+$H10)^($F10)),IF($D10="Fix",$G10,$G10*(1+$H10)^(2038-$E10)))))) | AD10: =IF($A10="","",IF(2039<$E10,"",IF($D10="Manuell","",IF(2039>$E10+$F10,IF($D10="Fix",$G10,$G10*(1+$H10)^($F10)),IF($D10="Fix",$G10,$G10*(1+$H10)^(2039-$E10)))))) | AE10: =IF($A10="","",IF(2040<$E10,"",IF($D10="Manuell","",IF(2040>$E10+$F10,IF($D10="Fix",$G10,$G10*(1+$H10)^($F10)),IF($D10="Fix",$G10,$G10*(1+$H10)^(2040-$E10)))))) | AF10: =IF($A10="","",IF(2041<$E10,"",IF($D10="Manuell","",IF(2041>$E10+$F10,IF($D10="Fix",$G10,$G10*(1+$H10)^($F10)),IF($D10="Fix",$G10,$G10*(1+$H10)^(2041-$E10)))))) | AG10: =IF($A10="","",IF(2042<$E10,"",IF($D10="Manuell","",IF(2042>$E10+$F10,IF($D10="Fix",$G10,$G10*(1+$H10)^($F10)),IF($D10="Fix",$G10,$G10*(1+$H10)^(2042-$E10)))))) | AH10: =IF($A10="","",IF(2043<$E10,"",IF($D10="Manuell","",IF(2043>$E10+$F10,IF($D10="Fix",$G10,$G10*(1+$H10)^($F10)),IF($D10="Fix",$G10,$G10*(1+$H10)^(2043-$E10)))))) | AI10: =IF($A10="","",IF(2044<$E10,"",IF($D10="Manuell","",IF(2044>$E10+$F10,IF($D10="Fix",$G10,$G10*(1+$H10)^($F10)),IF($D10="Fix",$G10,$G10*(1+$H10)^(2044-$E10)))))) | AJ10: =IF($A10="","",IF(2045<$E10,"",IF($D10="Manuell","",IF(2045>$E10+$F10,IF($D10="Fix",$G10,$G10*(1+$H10)^($F10)),IF($D10="Fix",$G10,$G10*(1+$H10)^(2045-$E10)))))) | AK10: =IF($A10="","",IF(2046<$E10,"",IF($D10="Manuell","",IF(2046>$E10+$F10,IF($D10="Fix",$G10,$G10*(1+$H10)^($F10)),IF($D10="Fix",$G10,$G10*(1+$H10)^(2046-$E10)))))) | AL10: =IF($A10="","",IF(2047<$E10,"",IF($D10="Manuell","",IF(2047>$E10+$F10,IF($D10="Fix",$G10,$G10*(1+$H10)^($F10)),IF($D10="Fix",$G10,$G10*(1+$H10)^(2047-$E10)))))) | AM10: =IF($A10="","",IF(2048<$E10,"",IF($D10="Manuell","",IF(2048>$E10+$F10,IF($D10="Fix",$G10,$G10*(1+$H10)^($F10)),IF($D10="Fix",$G10,$G10*(1+$H10)^(2048-$E10)))))) | AN10: =IF($A10="","",IF(2049<$E10,"",IF($D10="Manuell","",IF(2049>$E10+$F10,IF($D10="Fix",$G10,$G10*(1+$H10)^($F10)),IF($D10="Fix",$G10,$G10*(1+$H10)^(2049-$E10)))))) | AO10: =IF($A10="","",IF(2050<$E10,"",IF($D10="Manuell","",IF(2050>$E10+$F10,IF($D10="Fix",$G10,$G10*(1+$H10)^($F10)),IF($D10="Fix",$G10,$G10*(1+$H10)^(2050-$E10)))))) | AP10: =IF($A10="","",IF(2051<$E10,"",IF($D10="Manuell","",IF(2051>$E10+$F10,IF($D10="Fix",$G10,$G10*(1+$H10)^($F10)),IF($D10="Fix",$G10,$G10*(1+$H10)^(2051-$E10)))))) | AQ10: =IF($A10="","",IF(2052<$E10,"",IF($D10="Manuell","",IF(2052>$E10+$F10,IF($D10="Fix",$G10,$G10*(1+$H10)^($F10)),IF($D10="Fix",$G10,$G10*(1+$H10)^(2052-$E10)))))) | AR10: =IF($A10="","",IF(2053<$E10,"",IF($D10="Manuell","",IF(2053>$E10+$F10,IF($D10="Fix",$G10,$G10*(1+$H10)^($F10)),IF($D10="Fix",$G10,$G10*(1+$H10)^(2053-$E10)))))) | AS10: =IF($A10="","",IF(2054<$E10,"",IF($D10="Manuell","",IF(2054>$E10+$F10,IF($D10="Fix",$G10,$G10*(1+$H10)^($F10)),IF($D10="Fix",$G10,$G10*(1+$H10)^(2054-$E10)))))) | AT10: =IF($A10="","",IF(2055<$E10,"",IF($D10="Manuell","",IF(2055>$E10+$F10,IF($D10="Fix",$G10,$G10*(1+$H10)^($F10)),IF($D10="Fix",$G10,$G10*(1+$H10)^(2055-$E10))))))
I11: =IF($A11="","",IF(2018<$E11,"",IF($D11="Manuell","",IF(2018>$E11+$F11,IF($D11="Fix",$G11,$G11*(1+$H11)^($F11)),IF($D11="Fix",$G11,$G11*(1+$H11)^(2018-$E11)))))) | J11: =IF($A11="","",IF(2019<$E11,"",IF($D11="Manuell","",IF(2019>$E11+$F11,IF($D11="Fix",$G11,$G11*(1+$H11)^($F11)),IF($D11="Fix",$G11,$G11*(1+$H11)^(2019-$E11)))))) | K11: =IF($A11="","",IF(2020<$E11,"",IF($D11="Manuell","",IF(2020>$E11+$F11,IF($D11="Fix",$G11,$G11*(1+$H11)^($F11)),IF($D11="Fix",$G11,$G11*(1+$H11)^(2020-$E11)))))) | L11: =IF($A11="","",IF(2021<$E11,"",IF($D11="Manuell","",IF(2021>$E11+$F11,IF($D11="Fix",$G11,$G11*(1+$H11)^($F11)),IF($D11="Fix",$G11,$G11*(1+$H11)^(2021-$E11)))))) | M11: =IF($A11="","",IF(2022<$E11,"",IF($D11="Manuell","",IF(2022>$E11+$F11,IF($D11="Fix",$G11,$G11*(1+$H11)^($F11)),IF($D11="Fix",$G11,$G11*(1+$H11)^(2022-$E11)))))) | N11: =IF($A11="","",IF(2023<$E11,"",IF($D11="Manuell","",IF(2023>$E11+$F11,IF($D11="Fix",$G11,$G11*(1+$H11)^($F11)),IF($D11="Fix",$G11,$G11*(1+$H11)^(2023-$E11)))))) | O11: =IF($A11="","",IF(2024<$E11,"",IF($D11="Manuell","",IF(2024>$E11+$F11,IF($D11="Fix",$G11,$G11*(1+$H11)^($F11)),IF($D11="Fix",$G11,$G11*(1+$H11)^(2024-$E11)))))) | P11: =IF($A11="","",IF(2025<$E11,"",IF($D11="Manuell","",IF(2025>$E11+$F11,IF($D11="Fix",$G11,$G11*(1+$H11)^($F11)),IF($D11="Fix",$G11,$G11*(1+$H11)^(2025-$E11)))))) | Q11: =IF($A11="","",IF(2026<$E11,"",IF($D11="Manuell","",IF(2026>$E11+$F11,IF($D11="Fix",$G11,$G11*(1+$H11)^($F11)),IF($D11="Fix",$G11,$G11*(1+$H11)^(2026-$E11)))))) | R11: =IF($A11="","",IF(2027<$E11,"",IF($D11="Manuell","",IF(2027>$E11+$F11,IF($D11="Fix",$G11,$G11*(1+$H11)^($F11)),IF($D11="Fix",$G11,$G11*(1+$H11)^(2027-$E11)))))) | S11: =IF($A11="","",IF(2028<$E11,"",IF($D11="Manuell","",IF(2028>$E11+$F11,IF($D11="Fix",$G11,$G11*(1+$H11)^($F11)),IF($D11="Fix",$G11,$G11*(1+$H11)^(2028-$E11)))))) | T11: =IF($A11="","",IF(2029<$E11,"",IF($D11="Manuell","",IF(2029>$E11+$F11,IF($D11="Fix",$G11,$G11*(1+$H11)^($F11)),IF($D11="Fix",$G11,$G11*(1+$H11)^(2029-$E11)))))) | U11: =IF($A11="","",IF(2030<$E11,"",IF($D11="Manuell","",IF(2030>$E11+$F11,IF($D11="Fix",$G11,$G11*(1+$H11)^($F11)),IF($D11="Fix",$G11,$G11*(1+$H11)^(2030-$E11)))))) | V11: =IF($A11="","",IF(2031<$E11,"",IF($D11="Manuell","",IF(2031>$E11+$F11,IF($D11="Fix",$G11,$G11*(1+$H11)^($F11)),IF($D11="Fix",$G11,$G11*(1+$H11)^(2031-$E11)))))) | W11: =IF($A11="","",IF(2032<$E11,"",IF($D11="Manuell","",IF(2032>$E11+$F11,IF($D11="Fix",$G11,$G11*(1+$H11)^($F11)),IF($D11="Fix",$G11,$G11*(1+$H11)^(2032-$E11)))))) | X11: =IF($A11="","",IF(2033<$E11,"",IF($D11="Manuell","",IF(2033>$E11+$F11,IF($D11="Fix",$G11,$G11*(1+$H11)^($F11)),IF($D11="Fix",$G11,$G11*(1+$H11)^(2033-$E11)))))) | Y11: =IF($A11="","",IF(2034<$E11,"",IF($D11="Manuell","",IF(2034>$E11+$F11,IF($D11="Fix",$G11,$G11*(1+$H11)^($F11)),IF($D11="Fix",$G11,$G11*(1+$H11)^(2034-$E11)))))) | Z11: =IF($A11="","",IF(2035<$E11,"",IF($D11="Manuell","",IF(2035>$E11+$F11,IF($D11="Fix",$G11,$G11*(1+$H11)^($F11)),IF($D11="Fix",$G11,$G11*(1+$H11)^(2035-$E11)))))) | AA11: =IF($A11="","",IF(2036<$E11,"",IF($D11="Manuell","",IF(2036>$E11+$F11,IF($D11="Fix",$G11,$G11*(1+$H11)^($F11)),IF($D11="Fix",$G11,$G11*(1+$H11)^(2036-$E11)))))) | AB11: =IF($A11="","",IF(2037<$E11,"",IF($D11="Manuell","",IF(2037>$E11+$F11,IF($D11="Fix",$G11,$G11*(1+$H11)^($F11)),IF($D11="Fix",$G11,$G11*(1+$H11)^(2037-$E11)))))) | AC11: =IF($A11="","",IF(2038<$E11,"",IF($D11="Manuell","",IF(2038>$E11+$F11,IF($D11="Fix",$G11,$G11*(1+$H11)^($F11)),IF($D11="Fix",$G11,$G11*(1+$H11)^(2038-$E11)))))) | AD11: =IF($A11="","",IF(2039<$E11,"",IF($D11="Manuell","",IF(2039>$E11+$F11,IF($D11="Fix",$G11,$G11*(1+$H11)^($F11)),IF($D11="Fix",$G11,$G11*(1+$H11)^(2039-$E11)))))) | AE11: =IF($A11="","",IF(2040<$E11,"",IF($D11="Manuell","",IF(2040>$E11+$F11,IF($D11="Fix",$G11,$G11*(1+$H11)^($F11)),IF($D11="Fix",$G11,$G11*(1+$H11)^(2040-$E11)))))) | AF11: =IF($A11="","",IF(2041<$E11,"",IF($D11="Manuell","",IF(2041>$E11+$F11,IF($D11="Fix",$G11,$G11*(1+$H11)^($F11)),IF($D11="Fix",$G11,$G11*(1+$H11)^(2041-$E11)))))) | AG11: =IF($A11="","",IF(2042<$E11,"",IF($D11="Manuell","",IF(2042>$E11+$F11,IF($D11="Fix",$G11,$G11*(1+$H11)^($F11)),IF($D11="Fix",$G11,$G11*(1+$H11)^(2042-$E11)))))) | AH11: =IF($A11="","",IF(2043<$E11,"",IF($D11="Manuell","",IF(2043>$E11+$F11,IF($D11="Fix",$G11,$G11*(1+$H11)^($F11)),IF($D11="Fix",$G11,$G11*(1+$H11)^(2043-$E11)))))) | AI11: =IF($A11="","",IF(2044<$E11,"",IF($D11="Manuell","",IF(2044>$E11+$F11,IF($D11="Fix",$G11,$G11*(1+$H11)^($F11)),IF($D11="Fix",$G11,$G11*(1+$H11)^(2044-$E11)))))) | AJ11: =IF($A11="","",IF(2045<$E11,"",IF($D11="Manuell","",IF(2045>$E11+$F11,IF($D11="Fix",$G11,$G11*(1+$H11)^($F11)),IF($D11="Fix",$G11,$G11*(1+$H11)^(2045-$E11)))))) | AK11: =IF($A11="","",IF(2046<$E11,"",IF($D11="Manuell","",IF(2046>$E11+$F11,IF($D11="Fix",$G11,$G11*(1+$H11)^($F11)),IF($D11="Fix",$G11,$G11*(1+$H11)^(2046-$E11)))))) | AL11: =IF($A11="","",IF(2047<$E11,"",IF($D11="Manuell","",IF(2047>$E11+$F11,IF($D11="Fix",$G11,$G11*(1+$H11)^($F11)),IF($D11="Fix",$G11,$G11*(1+$H11)^(2047-$E11)))))) | AM11: =IF($A11="","",IF(2048<$E11,"",IF($D11="Manuell","",IF(2048>$E11+$F11,IF($D11="Fix",$G11,$G11*(1+$H11)^($F11)),IF($D11="Fix",$G11,$G11*(1+$H11)^(2048-$E11)))))) | AN11: =IF($A11="","",IF(2049<$E11,"",IF($D11="Manuell","",IF(2049>$E11+$F11,IF($D11="Fix",$G11,$G11*(1+$H11)^($F11)),IF($D11="Fix",$G11,$G11*(1+$H11)^(2049-$E11)))))) | AO11: =IF($A11="","",IF(2050<$E11,"",IF($D11="Manuell","",IF(2050>$E11+$F11,IF($D11="Fix",$G11,$G11*(1+$H11)^($F11)),IF($D11="Fix",$G11,$G11*(1+$H11)^(2050-$E11)))))) | AP11: =IF($A11="","",IF(2051<$E11,"",IF($D11="Manuell","",IF(2051>$E11+$F11,IF($D11="Fix",$G11,$G11*(1+$H11)^($F11)),IF($D11="Fix",$G11,$G11*(1+$H11)^(2051-$E11)))))) | AQ11: =IF($A11="","",IF(2052<$E11,"",IF($D11="Manuell","",IF(2052>$E11+$F11,IF($D11="Fix",$G11,$G11*(1+$H11)^($F11)),IF($D11="Fix",$G11,$G11*(1+$H11)^(2052-$E11)))))) | AR11: =IF($A11="","",IF(2053<$E11,"",IF($D11="Manuell","",IF(2053>$E11+$F11,IF($D11="Fix",$G11,$G11*(1+$H11)^($F11)),IF($D11="Fix",$G11,$G11*(1+$H11)^(2053-$E11)))))) | AS11: =IF($A11="","",IF(2054<$E11,"",IF($D11="Manuell","",IF(2054>$E11+$F11,IF($D11="Fix",$G11,$G11*(1+$H11)^($F11)),IF($D11="Fix",$G11,$G11*(1+$H11)^(2054-$E11)))))) | AT11: =IF($A11="","",IF(2055<$E11,"",IF($D11="Manuell","",IF(2055>$E11+$F11,IF($D11="Fix",$G11,$G11*(1+$H11)^($F11)),IF($D11="Fix",$G11,$G11*(1+$H11)^(2055-$E11))))))
